Workbook

Sheet G_Entregas
A1: Etiquetas | B1: UF Destino | C1: Cód. Winthor | D1: [Item] Descrição | E1: [Item] Quantidade | F1: [Item] Data de validade | G1: Nome PJ Emitente | H1: Número | I1: Data Emissão | J1: Mês | K1: Valor Total da Nota | L1: NFs Entrada - Winthor | M1: Previsão De Entrega
A2: PRIVADO | B2: PB | C2: 2187 | D2: IV FIX- FIXADOR ESTERIL IV FIX- FIXADOR ESTERIL | E2: 8 | F2: 46579 | G2: 3M DO BRASIL LTDA | H2: 522375 | I2: 45925 | J2: set | K2: 755.76 | L2: Pendente | M2: =_xlfn.XLOOKUP(relatorio_NF[[#This Row],[Número]],'relatorio_NF'!D:D,'relatorio_NF'!U:U) -> 45936
A3: PRIVADO | B3: PB | C3: 2187 | D3: IV FIX- FIXADOR ESTERIL IV FIX- FIXADOR ESTERIL | E3: 32 | F3: 46579 | G3: 3M DO BRASIL LTDA | H3: 522376 | I3: 45925 | J3: set | K3: 3000.96 | L3: Pendente | M3: =_xlfn.XLOOKUP(relatorio_NF[[#This Row],[Número]],'relatorio_NF'!D:D,'relatorio_NF'!U:U) -> 45936
A4: PUBLICO | B4: PE | C4: 869 | D4: DIPRIVAN 1% PFS 1X50ML BR (C1) ASP | E4: 200 | F4: 46386 | G4: Aspen Pharma Industria Farmaceutica Ltda | H4: 267737 | I4: 45924 | J4: set | K4: 34704 | L4: Pendente | M4: =_xlfn.XLOOKUP(relatorio_NF[[#This Row],[Número]],'relatorio_NF'!D:D,'relatorio_NF'!U:U) -> 45930
A5: PRIVADO | B5: PE | C5: 2382 | D5: NUBEQA 300MG TAFI BT 1X120 BR | E5: 15 | F5: 46721 | G5: Bayer S/A | H5: 288919 | I5: 45924 | J5: set | K5: 176334.37 | L5: Pendente | M5: =_xlfn.XLOOKUP(relatorio_NF[[#This Row],[Número]],'relatorio_NF'!D:D,'relatorio_NF'!U:U) -> 45936
A6: PUBLICO, VALOR DIVERGENTE (PÚBLICO ) | B6: PE | C6: 1514 | D6: URBANIL CPR 10MG X 20 M8 | E6: 45 | F6: 46568 | G6: MOKSHA8 BRASIL INDUSTRIA E COM | H6: 57029 | I6: 45924 | J6: set | K6: 384.62 | L6: Pendente | M6: =_xlfn.XLOOKUP(relatorio_NF[[#This Row],[Número]],'relatorio_NF'!D:D,'relatorio_NF'!U:U) -> 45943
A7: PUBLICO | B7: PB | C7: 3092 | D7: XTANDI TAB 40 4X28 BR | E7: 6 | F7: 46752 | G7: Astellas Farma Brasil Imp e Distrib de Medicamentos Ltda. | H7: 56041 | I7: 45924 | J7: set | K7: 52202.32 | L7: Pendente | M7: =_xlfn.XLOOKUP(relatorio_NF[[#This Row],[Número]],'relatorio_NF'!D:D,'relatorio_NF'!U:U) -> 45932
A8: PUBLICO | B8: PB | C8: 1430 | D8: VOTRIENT 400MG 60 CE | E8: 6 | F8: 46568 | G8: NOVARTIS BIOCIENCIAS SA | H8: 502164 | I8: 45924 | J8: set | K8: 47248.51 | L8: Pendente | M8: =_xlfn.XLOOKUP(relatorio_NF[[#This Row],[Número]],'relatorio_NF'!D:D,'relatorio_NF'!U:U) -> 45936
A9: PUBLICO | B9: PB | C9: 3759 | D9: KISQALI 200 MG 63 CE | E9: 44 | F9: 46326 | G9: NOVARTIS BIOCIENCIAS SA | H9: 502165 | I9: 45924 | J9: set | K9: 517591.34 | L9: Pendente | M9: =_xlfn.XLOOKUP(relatorio_NF[[#This Row],[Número]],'relatorio_NF'!D:D,'relatorio_NF'!U:U) -> 45936
A10: PUBLICO | B10: PB | C10: 2438 | D10: XOLAIR 150MG/1ML (1) SERINGA | E10: 408 | F10: 46265 | G10: NOVARTIS BIOCIENCIAS SA | H10: 50115 | I10: 45924 | J10: set | K10: 160113.55 | L10: Pendente | M10: =_xlfn.XLOOKUP(relatorio_NF[[#This Row],[Número]],'relatorio_NF'!D:D,'relatorio_NF'!U:U) -> 45929
A11: PUBLICO | B11: CE | C11: 2382 | D11: NUBEQA 300MG TAFI BT 1X120 BR | E11: 6 | F11: 46721 | G11: Bayer S/A | H11: 288743 | I11: 45924 | J11: set | K11: 70914.62 | L11: Pendente | M11: =_xlfn.XLOOKUP(relatorio_NF[[#This Row],[Número]],'relatorio_NF'!D:D,'relatorio_NF'!U:U) -> 45936
A12: PRIVADO | B12: CE | C12: 2382 | D12: NUBEQA 300MG TAFI BT 1X120 BR | E12: 15 | F12: 46721 | G12: Bayer S/A | H12: 288920 | I12: 45924 | J12: set | K12: 176332.6 | L12: Pendente | M12: =_xlfn.XLOOKUP(relatorio_NF[[#This Row],[Número]],'relatorio_NF'!D:D,'relatorio_NF'!U:U) -> 45936
A13: PRIVADO | B13: CE | C13: 2575 | D13: ONTAX 300 MG OR | E13: 1 | F13: 46568 | G13: LIBBS FARMACEUTICA Ltda | H13: 343366 | I13: 45924 | J13: set | K13: 318.86 | L13: Pendente | M13: =_xlfn.XLOOKUP(relatorio_NF[[#This Row],[Número]],'relatorio_NF'!D:D,'relatorio_NF'!U:U) -> 45931
... A82: PRIVADO | B82: PE | C82: 2421 | D82: HERZUMA 440 MG/20ML LOTE 5A6C222 Fab.:5/7/2025 Val.:2/28/2031 | E82: 48 | F82: 47907 | G82: CELLTRION HEALTHCARE DIST PROD FARMACEUTICOS DO BRASIL LTDA | H82: 8207 | I82: 45919 | J82: set | K82: 66240 | L82: Pendente | M82: =_xlfn.XLOOKUP(relatorio_NF[[#This Row],[Número]],'relatorio_NF'!D:D,'relatorio_NF'!U:U) -> 45929
A83: PUBLICO | B83: PE | C83: 3143 | D83: CANULA NASAL PARA OXIGENOTERAPIA GMI FR:06 - 2,10 M (NEONATAL) | E83: 300 | G83: GABISA MEDICAL INTERNATIONAL S.A. | H83: 36372 | I83: 45919 | J83: set | K83: 4904.17 | L83: Pendente | M83: =_xlfn.XLOOKUP(relatorio_NF[[#This Row],[Número]],'relatorio_NF'!D:D,'relatorio_NF'!U:U) -> 45943
A84: PUBLICO | B84: PE | C84: 3329 | D84: 1657R TEGADERM CHG CX C/25 3M TEGADERM CHG | E84: 40 | F84: 46471 | G84: 3M DO BRASIL LTDA | H84: 511798 | I84: 45919 | J84: set | K84: 50686.4 | L84: Pendente | M84: =_xlfn.XLOOKUP(relatorio_NF[[#This Row],[Número]],'relatorio_NF'!D:D,'relatorio_NF'!U:U) -> 45933
A85: PRIVADO | B85: PE | C85: 1344 | D85: REVOLADE 50MG 14 CE | E85: 5 | F85: 46446 | G85: NOVARTIS BIOCIENCIAS SA | H85: 501817 | I85: 45919 | J85: set | K85: 20125.53 | L85: Pendente | M85: =_xlfn.XLOOKUP(relatorio_NF[[#This Row],[Número]],'relatorio_NF'!D:D,'relatorio_NF'!U:U) -> 45929
A86: PRIVADO | B86: PB | C86: 3280 | D86: YUFLYMA SC 40MG/0,4ML LOTE 3LAT06T1D Fab.:9/19/2023 Val.:8/31/2026 | E86: 60 | F86: 46265 | G86: CELLTRION HEALTHCARE DIST PROD FARMACEUTICOS DO BRASIL LTDA | H86: 8204 | I86: 45919 | J86: set | K86: 52231.2 | L86: Pendente | M86: =_xlfn.XLOOKUP(relatorio_NF[[#This Row],[Número]],'relatorio_NF'!D:D,'relatorio_NF'!U:U) -> 45926
A87: PRIVADO | B87: PB | C87: 3143 | D87: CANULA NASAL PARA OXIGENOTERAPIA GMI FR:06 - 2,10 M (NEONATAL) | E87: 144 | G87: GABISA MEDICAL INTERNATIONAL S.A. | H87: 36370 | I87: 45919 | J87: set | K87: 2827.7 | L87: Pendente | M87: =_xlfn.XLOOKUP(relatorio_NF[[#This Row],[Número]],'relatorio_NF'!D:D,'relatorio_NF'!U:U) -> 45943
A88: PRIVADO | B88: PB | C88: 3149 | D88: CATETER UMBILICAL GMI FR:2,5 | E88: 10 | G88: GABISA MEDICAL INTERNATIONAL S.A. | H88: 36370 | I88: 45919 | J88: set | K88: 2827.7 | L88: Pendente | M88: =_xlfn.XLOOKUP(relatorio_NF[[#This Row],[Número]],'relatorio_NF'!D:D,'relatorio_NF'!U:U) -> 45943
A89: PRIVADO | B89: PB | C89: 3155 | D89: GABILINK - EXTENSOR VALVULADO SAFETY GMI NEONATAL 2 VIAS | E89: 50 | G89: GABISA MEDICAL INTERNATIONAL S.A. | H89: 36370 | I89: 45919 | J89: set | K89: 2827.7 | L89: Pendente | M89: =_xlfn.XLOOKUP(relatorio_NF[[#This Row],[Número]],'relatorio_NF'!D:D,'relatorio_NF'!U:U) -> 45943
A90: PRIVADO | B90: PB | C90: 3762 | D90: 54500 MANTA AQ UNDBD AD C/10 3M BAIR HUGGER MANTA 54500 | E90: 2 | F90: 46877 | G90: 3M DO BRASIL LTDA | H90: 511799 | I90: 45919 | J90: set | K90: 3259.43 | L90: Pendente | M90: =_xlfn.XLOOKUP(relatorio_NF[[#This Row],[Número]],'relatorio_NF'!D:D,'relatorio_NF'!U:U)
A91: PRIVADO | B91: PB | C91: 2335 | D91: 52500 MANTA AQ MEMBRO INF C/10 3M BAIR HUGGER MANTA 52500 | E91: 2 | F91: 46936 | G91: 3M DO BRASIL LTDA | H91: 511799 | I91: 45919 | J91: set | K91: 3259.43 | L91: Pendente | M91: =_xlfn.XLOOKUP(relatorio_NF[[#This Row],[Número]],'relatorio_NF'!D:D,'relatorio_NF'!U:U)
A92: PUBLICO | B92: PB | C92: 1296 | D92: MEKINIST 2MG 30 CE | E92: 6 | F92: 46326 | G92: NOVARTIS BIOCIENCIAS SA | H92: 501806 | I92: 45919 | J92: set | K92: 83577.69 | L92: Pendente | M92: =_xlfn.XLOOKUP(relatorio_NF[[#This Row],[Número]],'relatorio_NF'!D:D,'relatorio_NF'!U:U) -> 45929
A93: PUBLICO | B93: PB | C93: 1296 | D93: MEKINIST 2MG 30 CE | E93: 2 | F93: 46295 | G93: NOVARTIS BIOCIENCIAS SA | H93: 501807 | I93: 45919 | J93: set | K93: 27859.23 | L93: Pendente | M93: =_xlfn.XLOOKUP(relatorio_NF[[#This Row],[Número]],'relatorio_NF'!D:D,'relatorio_NF'!U:U) -> 45929
A94: PRIVADO | B94: CE | C94: 3199 | D94: ZEJULA 100MG 56CAPS | E94: 2 | F94: 46326 | G94: GLAXOSMITHKLINE BRASIL LTDA | H94: 251539 | I94: 45919 | J94: set | K94: 62349.98 | L94: Pendente | M94: =_xlfn.XLOOKUP(relatorio_NF[[#This Row],[Número]],'relatorio_NF'!D:D,'relatorio_NF'!U:U) -> 45925
A95: PRIVADO | B95: CE | C95: 3335 | D95: ZEJULA 100MG 28CAPS | E95: 2 | F95: 46326 | G95: GLAXOSMITHKLINE BRASIL LTDA | H95: 251539 | I95: 45919 | J95: set | K95: 62349.98 | L95: Pendente | M95: =_xlfn.XLOOKUP(relatorio_NF[[#This Row],[Número]],'relatorio_NF'!D:D,'relatorio_NF'!U:U) -> 45925
A96: PRIVADO | B96: CE | C96: 3335 | D96: ZEJULA 100MG 28CAPS | E96: 1 | F96: 46326 | G96: GLAXOSMITHKLINE BRASIL LTDA | H96: 251540 | I96: 45919 | J96: set | K96: 9407.19 | L96: Pendente | M96: =_xlfn.XLOOKUP(relatorio_NF[[#This Row],[Número]],'relatorio_NF'!D:D,'relatorio_NF'!U:U) -> 45926
A97: PRIVADO | B97: CE | C97: 3199 | D97: ZEJULA 100MG 56CAPS | E97: 1 | F97: 46326 | G97: GLAXOSMITHKLINE BRASIL LTDA | H97: 251541 | I97: 45919 | J97: set | K97: 19689.47 | L97: Pendente | M97: =_xlfn.XLOOKUP(relatorio_NF[[#This Row],[Número]],'relatorio_NF'!D:D,'relatorio_NF'!U:U) -> 45925
A98: PRIVADO | B98: CE | C98: 2889 | D98: VERZENIOS 150MG X30 COMP BL | E98: 20 | F98: 46507 | G98: Eli Lilly do Brasil Ltda. | H98: 447284 | I98: 45919 | J98: set | K98: 142850.65 | L98: Pendente | M98: =_xlfn.XLOOKUP(relatorio_NF[[#This Row],[Número]],'relatorio_NF'!D:D,'relatorio_NF'!U:U) -> 45936
A99: PRIVADO | B99: CE | C99: 3330 | D99: TALTZ AUTOINJECTOR 80MG X 1PEND BL | E99: 50 | F99: 46387 | G99: Eli Lilly do Brasil Ltda. | H99: 447293 | I99: 45919 | J99: set | K99: 222262.18 | L99: Pendente | M99: =_xlfn.XLOOKUP(relatorio_NF[[#This Row],[Número]],'relatorio_NF'!D:D,'relatorio_NF'!U:U) -> 45929
A100: PRIVADO | B100: CE | C100: 3322 | D100: OLUMIANT 4MG X 30 COMP BL | E100: 4 | F100: 46660 | G100: Eli Lilly do Brasil Ltda. | H100: 447294 | I100: 45919 | J100: set | K100: 15615.56 | L100: Pendente | M100: =_xlfn.XLOOKUP(relatorio_NF[[#This Row],[Número]],'relatorio_NF'!D:D,'relatorio_NF'!U:U) -> 45930
A101: PRIVADO | B101: CE | C101: 768 | D101: SANDOSTATIN LAR MPVI 30 MG | E101: 30 | F101: 46812 | G101: NOVARTIS BIOCIENCIAS SA | H101: 501823 | I101: 45919 | J101: set | K101: 237342.09 | L101: Pendente | M101: =_xlfn.XLOOKUP(relatorio_NF[[#This Row],[Número]],'relatorio_NF'!D:D,'relatorio_NF'!U:U) -> 45929
... A166: PRIVADO | B166: CE | C166: 2175 | D166: 1530 50MMX10M CARRETEL FITA CIRURGICA HIPO. MICROPORE | E166: 3960 | F166: 46579 | G166: 3M DO BRASIL LTDA | H166: 509463 | I166: 45917 | J166: set | K166: 106791.55 | L166: Pendente | M166: =_xlfn.XLOOKUP(relatorio_NF[[#This Row],[Número]],'relatorio_NF'!D:D,'relatorio_NF'!U:U) -> 45936
A167: PRIVADO | B167: CE | C167: 2367 | D167: 2269T NEO 10 SC C/ 3 UNID CADA ELETRODO RED DOT | E167: 2 | G167: 3M DO BRASIL LTDA | H167: 509463 | I167: 45917 | J167: set | K167: 106791.55 | L167: Pendente | M167: =_xlfn.XLOOKUP(relatorio_NF[[#This Row],[Número]],'relatorio_NF'!D:D,'relatorio_NF'!U:U) -> 45936
A168: PRIVADO | B168: CE | C168: 2380 | D168: 9160F UNIVERSAL REM CX C/ 200 PLACA ELETROCIRURGICA | E168: 5400 | F168: 46775 | G168: 3M DO BRASIL LTDA | H168: 509463 | I168: 45917 | J168: set | K168: 106791.55 | L168: Pendente | M168: =_xlfn.XLOOKUP(relatorio_NF[[#This Row],[Número]],'relatorio_NF'!D:D,'relatorio_NF'!U:U) -> 45936
A169: PRIVADO | B169: CE | C169: 2332 | D169: 55501 MANTA AQ PED UNDERB C/10 3M BAIR HUGGER MANTA 55501 | E169: 15 | F169: 46862 | G169: 3M DO BRASIL LTDA | H169: 509463 | I169: 45917 | J169: set | K169: 106791.55 | L169: Pendente | M169: =_xlfn.XLOOKUP(relatorio_NF[[#This Row],[Número]],'relatorio_NF'!D:D,'relatorio_NF'!U:U) -> 45936
A170: PRIVADO | B170: CE | C170: 2335 | D170: 52500 MANTA AQ MEMBRO INF C/10 3M BAIR HUGGER MANTA 52500 | E170: 10 | F170: 46936 | G170: 3M DO BRASIL LTDA | H170: 509463 | I170: 45917 | J170: set | K170: 106791.55 | L170: Pendente | M170: =_xlfn.XLOOKUP(relatorio_NF[[#This Row],[Número]],'relatorio_NF'!D:D,'relatorio_NF'!U:U) -> 45936
A171: PRIVADO | B171: CE | C171: 2337 | D171: 63500 MANTA AQ UNDER COMPL C/5 3M BAIR HUGGER MANTA 63500 | E171: 92 | F171: 46945 | G171: 3M DO BRASIL LTDA | H171: 509463 | I171: 45917 | J171: set | K171: 106791.55 | L171: Pendente | M171: =_xlfn.XLOOKUP(relatorio_NF[[#This Row],[Número]],'relatorio_NF'!D:D,'relatorio_NF'!U:U) -> 45936
A172: PRIVADO | B172: CE | C172: 2248 | D172: COBAN NL 2082 50MMX4.5M 3M COBAN NL 2082 50MMX4.5M | E172: 540 | F172: 46910 | G172: 3M DO BRASIL LTDA | H172: 509464 | I172: 45917 | J172: set | K172: 6285.6 | L172: Pendente | M172: =_xlfn.XLOOKUP(relatorio_NF[[#This Row],[Número]],'relatorio_NF'!D:D,'relatorio_NF'!U:U) -> 45933
...

Sheet relatorio_NF
A1: Etiquetas | B1: UF Destino | C1: Nome PJ Emitente | D1: Número | E1: Data Emissão | F1: Valor Total da Nota | G1: [Item] EAN | H1: [Item] Código | I1: [Item] Descrição | J1: [Item] Data de validade | K1: [Item] Quantidade | L1: De_Para | M1: EAN | N1: Mês | O1: NFs Entrada - Winthor | P1: Natureza | Q1: Cód. Winthor | R1: CTE | S1: Dt. CTE | T1: Previsão de entrega - Bruto | U1: Previsão de entrega
A2: PRIVADO | B2: PB | C2: 3M DO BRASIL LTDA | D2: 522375 | E2: 45925 | F2: 755.76 | G2: 7891040118168 | H2: HB004244164 | I2: IV FIX- FIXADOR ESTERIL IV FIX- FIXADOR ESTERIL | J2: 46579 | K2: 8 | L2: =_xlfn.XLOOKUP(relatorio[[#This Row],[Nome PJ Emitente]],De_Para!A:A,De_Para!C:C) -> 3M | M2: {=IF(LEFT(G2&"",1)="0", IFERROR( VALUE(MID(G2&"",_xlfn.AGGREGATE(15,6,ROW(INDIRECT("1:"&LEN(G2&"")))/(MID(G2&"",ROW(INDIRECT("1:"&LEN(G2&""))),1)<>"0"),1),999)), MID(G2&"",_xlfn.AGGREGATE(15,6,ROW(INDIRECT("1:"&LEN(G2&"")))/(MID(G2&"",ROW(INDIRECT("1:"&LEN(G2&""))),1)<>"0"),1),999) ), IFERROR(VALUE(G2),G2))} -> 7891040118168 | N2: =TEXT(relatorio[[#This Row],[Data Emissão]],"mmm") -> set | O2: =_xlfn.XLOOKUP(relatorio[[#This Row],[Número]],relatorio_Entrada_NF!A:A,relatorio_Entrada_NF!A:A,"Pendente") -> Pendente | P2: =_xlfn.XLOOKUP(relatorio[[#This Row],[Nome PJ Emitente]],Material!A:A,Material!B:B,"Medicamento") -> Material | Q2: =IF(relatorio[[#This Row],[Natureza]]="Medicamento",_xlfn.XLOOKUP(relatorio[[#This Row],[EAN]],CadastroProd!U:U,CadastroProd!A:A," "),_xlfn.XLOOKUP(relatorio[[#This Row],['[Item'] Código]],CadastroProd!X:X,CadastroProd!A:A," ")) -> 2187 | R2: =IF(O2="Pendente",_xlfn.XLOOKUP(relatorio[[#This Row],[Número]],Relatório_CTE!A:A,Relatório_CTE!B:B,"Sem CTE")," ") -> Sem CTE | S2: =IF(relatorio[[#This Row],[NFs Entrada - Winthor]]="Pendente",_xlfn.XLOOKUP(relatorio[[#This Row],[Número]],Relatório_CTE!A:A,Relatório_CTE!H:H,"Sem CTE")," ") -> Sem CTE | T2: =(IF(relatorio[[#This Row],[NFs Entrada - Winthor]]="Pendente",IF(relatorio[[#This Row],[Dt. CTE]]="Sem CTE",relatorio[[#This Row],[Data Emissão]]+_xlfn.XLOOKUP(relatorio[[#This Row],[De_Para]],'Lead Time - Histórico (Fornec.)'!B:B,'Lead Time - Histórico (Fornec.)'!C:C),relatorio[[#This Row],[Dt. CTE]]+_xlfn.XLOOKUP(relatorio[[#This Row],[Cód. Winthor]],'Lead Time - Histórico (Produto)'!A:A,'Lead Time - Histórico (Produto)'!C:C))," ")) -> 45936 | U2: =IFERROR(IF(WEEKDAY(relatorio[[#This Row],[Previsão de entrega - Bruto]],2)=6,relatorio[[#This Row],[Previsão de entrega - Bruto]]+2,IF(WEEKDAY(relatorio[[#This Row],[Previsão de entrega - Bruto]],2)=7,relatorio[[#This Row],[Previsão de entrega - Bruto]]+1,relatorio[[#This Row],[Previsão de entrega - Bruto]]))," ") -> 45936
A3: PRIVADO | B3: PB | C3: 3M DO BRASIL LTDA | D3: 522376 | E3: 45925 | F3: 3000.96 | G3: 7891040118168 | H3: HB004244164 | I3: IV FIX- FIXADOR ESTERIL IV FIX- FIXADOR ESTERIL | J3: 46579 | K3: 32 | L3: =_xlfn.XLOOKUP(relatorio[[#This Row],[Nome PJ Emitente]],De_Para!A:A,De_Para!C:C) -> 3M | M3: {=IF(LEFT(G3&"",1)="0", IFERROR( VALUE(MID(G3&"",_xlfn.AGGREGATE(15,6,ROW(INDIRECT("1:"&LEN(G3&"")))/(MID(G3&"",ROW(INDIRECT("1:"&LEN(G3&""))),1)<>"0"),1),999)), MID(G3&"",_xlfn.AGGREGATE(15,6,ROW(INDIRECT("1:"&LEN(G3&"")))/(MID(G3&"",ROW(INDIRECT("1:"&LEN(G3&""))),1)<>"0"),1),999) ), IFERROR(VALUE(G3),G3))} -> 7891040118168 | N3: =TEXT(relatorio[[#This Row],[Data Emissão]],"mmm") -> set | O3: =_xlfn.XLOOKUP(relatorio[[#This Row],[Número]],relatorio_Entrada_NF!A:A,relatorio_Entrada_NF!A:A,"Pendente") -> Pendente | P3: =_xlfn.XLOOKUP(relatorio[[#This Row],[Nome PJ Emitente]],Material!A:A,Material!B:B,"Medicamento") -> Material | Q3: =IF(relatorio[[#This Row],[Natureza]]="Medicamento",_xlfn.XLOOKUP(relatorio[[#This Row],[EAN]],CadastroProd!U:U,CadastroProd!A:A," "),_xlfn.XLOOKUP(relatorio[[#This Row],['[Item'] Código]],CadastroProd!X:X,CadastroProd!A:A," ")) -> 2187 | R3: =IF(O3="Pendente",_xlfn.XLOOKUP(relatorio[[#This Row],[Número]],Relatório_CTE!A:A,Relatório_CTE!B:B,"Sem CTE")," ") -> Sem CTE | S3: =IF(relatorio[[#This Row],[NFs Entrada - Winthor]]="Pendente",_xlfn.XLOOKUP(relatorio[[#This Row],[Número]],Relatório_CTE!A:A,Relatório_CTE!H:H,"Sem CTE")," ") -> Sem CTE | T3: =(IF(relatorio[[#This Row],[NFs Entrada - Winthor]]="Pendente",IF(relatorio[[#This Row],[Dt. CTE]]="Sem CTE",relatorio[[#This Row],[Data Emissão]]+_xlfn.XLOOKUP(relatorio[[#This Row],[De_Para]],'Lead Time - Histórico (Fornec.)'!B:B,'Lead Time - Histórico (Fornec.)'!C:C),relatorio[[#This Row],[Dt. CTE]]+_xlfn.XLOOKUP(relatorio[[#This Row],[Cód. Winthor]],'Lead Time - Histórico (Produto)'!A:A,'Lead Time - Histórico (Produto)'!C:C))," ")) -> 45936 | U3: =IFERROR(IF(WEEKDAY(relatorio[[#This Row],[Previsão de entrega - Bruto]],2)=6,relatorio[[#This Row],[Previsão de entrega - Bruto]]+2,IF(WEEKDAY(relatorio[[#This Row],[Previsão de entrega - Bruto]],2)=7,relatorio[[#This Row],[Previsão de entrega - Bruto]]+1,relatorio[[#This Row],[Previsão de entrega - Bruto]]))," ") -> 45936
A4: PUBLICO | B4: PE | C4: Aspen Pharma Industria Farmaceutica Ltda | D4: 267737 | E4: 45924 | F4: 34704 | G4: 7895858016821 | H4: 000000000007057867 | I4: DIPRIVAN 1% PFS 1X50ML BR (C1) ASP | J4: 46386 | K4: 200 | L4: =_xlfn.XLOOKUP(relatorio[[#This Row],[Nome PJ Emitente]],De_Para!A:A,De_Para!C:C) -> Aspen | M4: {=IF(LEFT(G4&"",1)="0", IFERROR( VALUE(MID(G4&"",_xlfn.AGGREGATE(15,6,ROW(INDIRECT("1:"&LEN(G4&"")))/(MID(G4&"",ROW(INDIRECT("1:"&LEN(G4&""))),1)<>"0"),1),999)), MID(G4&"",_xlfn.AGGREGATE(15,6,ROW(INDIRECT("1:"&LEN(G4&"")))/(MID(G4&"",ROW(INDIRECT("1:"&LEN(G4&""))),1)<>"0"),1),999) ), IFERROR(VALUE(G4),G4))} -> 7895858016821 | N4: =TEXT(relatorio[[#This Row],[Data Emissão]],"mmm") -> set | O4: =_xlfn.XLOOKUP(relatorio[[#This Row],[Número]],relatorio_Entrada_NF!A:A,relatorio_Entrada_NF!A:A,"Pendente") -> Pendente | P4: =_xlfn.XLOOKUP(relatorio[[#This Row],[Nome PJ Emitente]],Material!A:A,Material!B:B,"Medicamento") -> Medicamento | Q4: =IF(relatorio[[#This Row],[Natureza]]="Medicamento",_xlfn.XLOOKUP(relatorio[[#This Row],[EAN]],CadastroProd!U:U,CadastroProd!A:A," "),_xlfn.XLOOKUP(relatorio[[#This Row],['[Item'] Código]],CadastroProd!X:X,CadastroProd!A:A," ")) -> 869 | R4: =IF(O4="Pendente",_xlfn.XLOOKUP(relatorio[[#This Row],[Número]],Relatório_CTE!A:A,Relatório_CTE!B:B,"Sem CTE")," ") -> Sem CTE | S4: =IF(relatorio[[#This Row],[NFs Entrada - Winthor]]="Pendente",_xlfn.XLOOKUP(relatorio[[#This Row],[Número]],Relatório_CTE!A:A,Relatório_CTE!H:H,"Sem CTE")," ") -> Sem CTE | T4: =(IF(relatorio[[#This Row],[NFs Entrada - Winthor]]="Pendente",IF(relatorio[[#This Row],[Dt. CTE]]="Sem CTE",relatorio[[#This Row],[Data Emissão]]+_xlfn.XLOOKUP(relatorio[[#This Row],[De_Para]],'Lead Time - Histórico (Fornec.)'!B:B,'Lead Time - Histórico (Fornec.)'!C:C),relatorio[[#This Row],[Dt. CTE]]+_xlfn.XLOOKUP(relatorio[[#This Row],[Cód. Winthor]],'Lead Time - Histórico (Produto)'!A:A,'Lead Time - Histórico (Produto)'!C:C))," ")) -> 45930 | U4: =IFERROR(IF(WEEKDAY(relatorio[[#This Row],[Previsão de entrega - Bruto]],2)=6,relatorio[[#This Row],[Previsão de entrega - Bruto]]+2,IF(WEEKDAY(relatorio[[#This Row],[Previsão de entrega - Bruto]],2)=7,relatorio[[#This Row],[Previsão de entrega - Bruto]]+1,relatorio[[#This Row],[Previsão de entrega - Bruto]]))," ") -> 45930
A5: PRIVADO | B5: PE | C5: Bayer S/A | D5: 288919 | E5: 45924 | F5: 176334.37 | G5: 7891106913881 | H5: 000000000086961458 | I5: NUBEQA 300MG TAFI BT 1X120 BR | J5: 46721 | K5: 15 | L5: =_xlfn.XLOOKUP(relatorio[[#This Row],[Nome PJ Emitente]],De_Para!A:A,De_Para!C:C) -> Bayer | M5: {=IF(LEFT(G5&"",1)="0", IFERROR( VALUE(MID(G5&"",_xlfn.AGGREGATE(15,6,ROW(INDIRECT("1:"&LEN(G5&"")))/(MID(G5&"",ROW(INDIRECT("1:"&LEN(G5&""))),1)<>"0"),1),999)), MID(G5&"",_xlfn.AGGREGATE(15,6,ROW(INDIRECT("1:"&LEN(G5&"")))/(MID(G5&"",ROW(INDIRECT("1:"&LEN(G5&""))),1)<>"0"),1),999) ), IFERROR(VALUE(G5),G5))} -> 7891106913881 | N5: =TEXT(relatorio[[#This Row],[Data Emissão]],"mmm") -> set | O5: =_xlfn.XLOOKUP(relatorio[[#This Row],[Número]],relatorio_Entrada_NF!A:A,relatorio_Entrada_NF!A:A,"Pendente") -> Pendente | P5: =_xlfn.XLOOKUP(relatorio[[#This Row],[Nome PJ Emitente]],Material!A:A,Material!B:B,"Medicamento") -> Medicamento | Q5: =IF(relatorio[[#This Row],[Natureza]]="Medicamento",_xlfn.XLOOKUP(relatorio[[#This Row],[EAN]],CadastroProd!U:U,CadastroProd!A:A," "),_xlfn.XLOOKUP(relatorio[[#This Row],['[Item'] Código]],CadastroProd!X:X,CadastroProd!A:A," ")) -> 2382 | R5: =IF(O5="Pendente",_xlfn.XLOOKUP(relatorio[[#This Row],[Número]],Relatório_CTE!A:A,Relatório_CTE!B:B,"Sem CTE")," ") -> Sem CTE | S5: =IF(relatorio[[#This Row],[NFs Entrada - Winthor]]="Pendente",_xlfn.XLOOKUP(relatorio[[#This Row],[Número]],Relatório_CTE!A:A,Relatório_CTE!H:H,"Sem CTE")," ") -> Sem CTE | T5: =(IF(relatorio[[#This Row],[NFs Entrada - Winthor]]="Pendente",IF(relatorio[[#This Row],[Dt. CTE]]="Sem CTE",relatorio[[#This Row],[Data Emissão]]+_xlfn.XLOOKUP(relatorio[[#This Row],[De_Para]],'Lead Time - Histórico (Fornec.)'!B:B,'Lead Time - Histórico (Fornec.)'!C:C),relatorio[[#This Row],[Dt. CTE]]+_xlfn.XLOOKUP(relatorio[[#This Row],[Cód. Winthor]],'Lead Time - Histórico (Produto)'!A:A,'Lead Time - Histórico (Produto)'!C:C))," ")) -> 45935 | U5: =IFERROR(IF(WEEKDAY(relatorio[[#This Row],[Previsão de entrega - Bruto]],2)=6,relatorio[[#This Row],[Previsão de entrega - Bruto]]+2,IF(WEEKDAY(relatorio[[#This Row],[Previsão de entrega - Bruto]],2)=7,relatorio[[#This Row],[Previsão de entrega - Bruto]]+1,relatorio[[#This Row],[Previsão de entrega - Bruto]]))," ") -> 45936
A6: PUBLICO, VALOR DIVERGENTE (PÚBLICO ) | B6: PE | C6: MOKSHA8 BRASIL INDUSTRIA E COM | D6: 57029 | E6: 45924 | F6: 384.62 | G6: 7898216367955 | H6: 100497 | I6: URBANIL CPR 10MG X 20 M8 | J6: 46568 | K6: 45 | L6: =_xlfn.XLOOKUP(relatorio[[#This Row],[Nome PJ Emitente]],De_Para!A:A,De_Para!C:C) -> Moksha8 | M6: {=IF(LEFT(G6&"",1)="0", IFERROR( VALUE(MID(G6&"",_xlfn.AGGREGATE(15,6,ROW(INDIRECT("1:"&LEN(G6&"")))/(MID(G6&"",ROW(INDIRECT("1:"&LEN(G6&""))),1)<>"0"),1),999)), MID(G6&"",_xlfn.AGGREGATE(15,6,ROW(INDIRECT("1:"&LEN(G6&"")))/(MID(G6&"",ROW(INDIRECT("1:"&LEN(G6&""))),1)<>"0"),1),999) ), IFERROR(VALUE(G6),G6))} -> 7898216367955 | N6: =TEXT(relatorio[[#This Row],[Data Emissão]],"mmm") -> set | O6: =_xlfn.XLOOKUP(relatorio[[#This Row],[Número]],relatorio_Entrada_NF!A:A,relatorio_Entrada_NF!A:A,"Pendente") -> Pendente | P6: =_xlfn.XLOOKUP(relatorio[[#This Row],[Nome PJ Emitente]],Material!A:A,Material!B:B,"Medicamento") -> Medicamento | Q6: =IF(relatorio[[#This Row],[Natureza]]="Medicamento",_xlfn.XLOOKUP(relatorio[[#This Row],[EAN]],CadastroProd!U:U,CadastroProd!A:A," "),_xlfn.XLOOKUP(relatorio[[#This Row],['[Item'] Código]],CadastroProd!X:X,CadastroProd!A:A," ")) -> 1514 | R6: =IF(O6="Pendente",_xlfn.XLOOKUP(relatorio[[#This Row],[Número]],Relatório_CTE!A:A,Relatório_CTE!B:B,"Sem CTE")," ") -> Sem CTE | S6: =IF(relatorio[[#This Row],[NFs Entrada - Winthor]]="Pendente",_xlfn.XLOOKUP(relatorio[[#This Row],[Número]],Relatório_CTE!A:A,Relatório_CTE!H:H,"Sem CTE")," ") -> Sem CTE | T6: =(IF(relatorio[[#This Row],[NFs Entrada - Winthor]]="Pendente",IF(relatorio[[#This Row],[Dt. CTE]]="Sem CTE",relatorio[[#This Row],[Data Emissão]]+_xlfn.XLOOKUP(relatorio[[#This Row],[De_Para]],'Lead Time - Histórico (Fornec.)'!B:B,'Lead Time - Histórico (Fornec.)'!C:C),relatorio[[#This Row],[Dt. CTE]]+_xlfn.XLOOKUP(relatorio[[#This Row],[Cód. Winthor]],'Lead Time - Histórico (Produto)'!A:A,'Lead Time - Histórico (Produto)'!C:C))," ")) -> 45942 | U6: =IFERROR(IF(WEEKDAY(relatorio[[#This Row],[Previsão de entrega - Bruto]],2)=6,relatorio[[#This Row],[Previsão de entrega - Bruto]]+2,IF(WEEKDAY(relatorio[[#This Row],[Previsão de entrega - Bruto]],2)=7,relatorio[[#This Row],[Previsão de entrega - Bruto]]+1,relatorio[[#This Row],[Previsão de entrega - Bruto]]))," ") -> 45943
A7: PUBLICO | B7: PB | C7: Astellas Farma Brasil Imp e Distrib de Medicamentos Ltda. | D7: 56041 | E7: 45924 | F7: 52202.32 | G7: 7899337001070 | H7: 1000861 | I7: XTANDI TAB 40 4X28 BR | J7: 46752 | K7: 6 | L7: =_xlfn.XLOOKUP(relatorio[[#This Row],[Nome PJ Emitente]],De_Para!A:A,De_Para!C:C) -> Astellas | M7: {=IF(LEFT(G7&"",1)="0", IFERROR( VALUE(MID(G7&"",_xlfn.AGGREGATE(15,6,ROW(INDIRECT("1:"&LEN(G7&"")))/(MID(G7&"",ROW(INDIRECT("1:"&LEN(G7&""))),1)<>"0"),1),999)), MID(G7&"",_xlfn.AGGREGATE(15,6,ROW(INDIRECT("1:"&LEN(G7&"")))/(MID(G7&"",ROW(INDIRECT("1:"&LEN(G7&""))),1)<>"0"),1),999) ), IFERROR(VALUE(G7),G7))} -> 7899337001070 | N7: =TEXT(relatorio[[#This Row],[Data Emissão]],"mmm") -> set | O7: =_xlfn.XLOOKUP(relatorio[[#This Row],[Número]],relatorio_Entrada_NF!A:A,relatorio_Entrada_NF!A:A,"Pendente") -> Pendente | P7: =_xlfn.XLOOKUP(relatorio[[#This Row],[Nome PJ Emitente]],Material!A:A,Material!B:B,"Medicamento") -> Medicamento | Q7: =IF(relatorio[[#This Row],[Natureza]]="Medicamento",_xlfn.XLOOKUP(relatorio[[#This Row],[EAN]],CadastroProd!U:U,CadastroProd!A:A," "),_xlfn.XLOOKUP(relatorio[[#This Row],['[Item'] Código]],CadastroProd!X:X,CadastroProd!A:A," ")) -> 3092 | R7: =IF(O7="Pendente",_xlfn.XLOOKUP(relatorio[[#This Row],[Número]],Relatório_CTE!A:A,Relatório_CTE!B:B,"Sem CTE")," ") -> Sem CTE | S7: =IF(relatorio[[#This Row],[NFs Entrada - Winthor]]="Pendente",_xlfn.XLOOKUP(relatorio[[#This Row],[Número]],Relatório_CTE!A:A,Relatório_CTE!H:H,"Sem CTE")," ") -> Sem CTE | T7: =(IF(relatorio[[#This Row],[NFs Entrada - Winthor]]="Pendente",IF(relatorio[[#This Row],[Dt. CTE]]="Sem CTE",relatorio[[#This Row],[Data Emissão]]+_xlfn.XLOOKUP(relatorio[[#This Row],[De_Para]],'Lead Time - Histórico (Fornec.)'!B:B,'Lead Time - Histórico (Fornec.)'!C:C),relatorio[[#This Row],[Dt. CTE]]+_xlfn.XLOOKUP(relatorio[[#This Row],[Cód. Winthor]],'Lead Time - Histórico (Produto)'!A:A,'Lead Time - Histórico (Produto)'!C:C))," ")) -> 45932 | U7: =IFERROR(IF(WEEKDAY(relatorio[[#This Row],[Previsão de entrega - Bruto]],2)=6,relatorio[[#This Row],[Previsão de entrega - Bruto]]+2,IF(WEEKDAY(relatorio[[#This Row],[Previsão de entrega - Bruto]],2)=7,relatorio[[#This Row],[Previsão de entrega - Bruto]]+1,relatorio[[#This Row],[Previsão de entrega - Bruto]]))," ") -> 45932
A8: PUBLICO | B8: PB | C8: NOVARTIS BIOCIENCIAS SA | D8: 502164 | E8: 45924 | F8: 47248.51 | G8: 7896261020795 | H8: 733310 | I8: VOTRIENT 400MG 60 CE | J8: 46568 | K8: 6 | L8: =_xlfn.XLOOKUP(relatorio[[#This Row],[Nome PJ Emitente]],De_Para!A:A,De_Para!C:C) -> Novartis | M8: {=IF(LEFT(G8&"",1)="0", IFERROR( VALUE(MID(G8&"",_xlfn.AGGREGATE(15,6,ROW(INDIRECT("1:"&LEN(G8&"")))/(MID(G8&"",ROW(INDIRECT("1:"&LEN(G8&""))),1)<>"0"),1),999)), MID(G8&"",_xlfn.AGGREGATE(15,6,ROW(INDIRECT("1:"&LEN(G8&"")))/(MID(G8&"",ROW(INDIRECT("1:"&LEN(G8&""))),1)<>"0"),1),999) ), IFERROR(VALUE(G8),G8))} -> 7896261020795 | N8: =TEXT(relatorio[[#This Row],[Data Emissão]],"mmm") -> set | O8: =_xlfn.XLOOKUP(relatorio[[#This Row],[Número]],relatorio_Entrada_NF!A:A,relatorio_Entrada_NF!A:A,"Pendente") -> Pendente | P8: =_xlfn.XLOOKUP(relatorio[[#This Row],[Nome PJ Emitente]],Material!A:A,Material!B:B,"Medicamento") -> Medicamento | Q8: =IF(relatorio[[#This Row],[Natureza]]="Medicamento",_xlfn.XLOOKUP(relatorio[[#This Row],[EAN]],CadastroProd!U:U,CadastroProd!A:A," "),_xlfn.XLOOKUP(relatorio[[#This Row],['[Item'] Código]],CadastroProd!X:X,CadastroProd!A:A," ")) -> 1430 | R8: =IF(O8="Pendente",_xlfn.XLOOKUP(relatorio[[#This Row],[Número]],Relatório_CTE!A:A,Relatório_CTE!B:B,"Sem CTE")," ") -> Sem CTE | S8: =IF(relatorio[[#This Row],[NFs Entrada - Winthor]]="Pendente",_xlfn.XLOOKUP(relatorio[[#This Row],[Número]],Relatório_CTE!A:A,Relatório_CTE!H:H,"Sem CTE")," ") -> Sem CTE | T8: =(IF(relatorio[[#This Row],[NFs Entrada - Winthor]]="Pendente",IF(relatorio[[#This Row],[Dt. CTE]]="Sem CTE",relatorio[[#This Row],[Data Emissão]]+_xlfn.XLOOKUP(relatorio[[#This Row],[De_Para]],'Lead Time - Histórico (Fornec.)'!B:B,'Lead Time - Histórico (Fornec.)'!C:C),relatorio[[#This Row],[Dt. CTE]]+_xlfn.XLOOKUP(relatorio[[#This Row],[Cód. Winthor]],'Lead Time - Histórico (Produto)'!A:A,'Lead Time - Histórico (Produto)'!C:C))," ")) -> 45934 | U8: =IFERROR(IF(WEEKDAY(relatorio[[#This Row],[Previsão de entrega - Bruto]],2)=6,relatorio[[#This Row],[Previsão de entrega - Bruto]]+2,IF(WEEKDAY(relatorio[[#This Row],[Previsão de entrega - Bruto]],2)=7,relatorio[[#This Row],[Previsão de entrega - Bruto]]+1,relatorio[[#This Row],[Previsão de entrega - Bruto]]))," ") -> 45936
A9: PUBLICO | B9: PB | C9: NOVARTIS BIOCIENCIAS SA | D9: 502165 | E9: 45924 | F9: 517591.34 | G9: 7896261023185 | H9: 302105 | I9: KISQALI 200 MG 63 CE | J9: 46326 | K9: 44 | L9: =_xlfn.XLOOKUP(relatorio[[#This Row],[Nome PJ Emitente]],De_Para!A:A,De_Para!C:C) -> Novartis | M9: {=IF(LEFT(G9&"",1)="0", IFERROR( VALUE(MID(G9&"",_xlfn.AGGREGATE(15,6,ROW(INDIRECT("1:"&LEN(G9&"")))/(MID(G9&"",ROW(INDIRECT("1:"&LEN(G9&""))),1)<>"0"),1),999)), MID(G9&"",_xlfn.AGGREGATE(15,6,ROW(INDIRECT("1:"&LEN(G9&"")))/(MID(G9&"",ROW(INDIRECT("1:"&LEN(G9&""))),1)<>"0"),1),999) ), IFERROR(VALUE(G9),G9))} -> 7896261023185 | N9: =TEXT(relatorio[[#This Row],[Data Emissão]],"mmm") -> set | O9: =_xlfn.XLOOKUP(relatorio[[#This Row],[Número]],relatorio_Entrada_NF!A:A,relatorio_Entrada_NF!A:A,"Pendente") -> Pendente | P9: =_xlfn.XLOOKUP(relatorio[[#This Row],[Nome PJ Emitente]],Material!A:A,Material!B:B,"Medicamento") -> Medicamento | Q9: =IF(relatorio[[#This Row],[Natureza]]="Medicamento",_xlfn.XLOOKUP(relatorio[[#This Row],[EAN]],CadastroProd!U:U,CadastroProd!A:A," "),_xlfn.XLOOKUP(relatorio[[#This Row],['[Item'] Código]],CadastroProd!X:X,CadastroProd!A:A," ")) -> 3759 | R9: =IF(O9="Pendente",_xlfn.XLOOKUP(relatorio[[#This Row],[Número]],Relatório_CTE!A:A,Relatório_CTE!B:B,"Sem CTE")," ") -> Sem CTE | S9: =IF(relatorio[[#This Row],[NFs Entrada - Winthor]]="Pendente",_xlfn.XLOOKUP(relatorio[[#This Row],[Número]],Relatório_CTE!A:A,Relatório_CTE!H:H,"Sem CTE")," ") -> Sem CTE | T9: =(IF(relatorio[[#This Row],[NFs Entrada - Winthor]]="Pendente",IF(relatorio[[#This Row],[Dt. CTE]]="Sem CTE",relatorio[[#This Row],[Data Emissão]]+_xlfn.XLOOKUP(relatorio[[#This Row],[De_Para]],'Lead Time - Histórico (Fornec.)'!B:B,'Lead Time - Histórico (Fornec.)'!C:C),relatorio[[#This Row],[Dt. CTE]]+_xlfn.XLOOKUP(relatorio[[#This Row],[Cód. Winthor]],'Lead Time - Histórico (Produto)'!A:A,'Lead Time - Histórico (Produto)'!C:C))," ")) -> 45934 | U9: =IFERROR(IF(WEEKDAY(relatorio[[#This Row],[Previsão de entrega - Bruto]],2)=6,relatorio[[#This Row],[Previsão de entrega - Bruto]]+2,IF(WEEKDAY(relatorio[[#This Row],[Previsão de entrega - Bruto]],2)=7,relatorio[[#This Row],[Previsão de entrega - Bruto]]+1,relatorio[[#This Row],[Previsão de entrega - Bruto]]))," ") -> 45936
A10: PUBLICO | B10: PB | C10: NOVARTIS BIOCIENCIAS SA | D10: 50115 | E10: 45924 | F10: 160113.55 | G10: 7896261020382 | H10: 749202 | I10: XOLAIR 150MG/1ML (1) SERINGA | J10: 46265 | K10: 408 | L10: =_xlfn.XLOOKUP(relatorio[[#This Row],[Nome PJ Emitente]],De_Para!A:A,De_Para!C:C) -> Novartis | M10: {=IF(LEFT(G10&"",1)="0", IFERROR( VALUE(MID(G10&"",_xlfn.AGGREGATE(15,6,ROW(INDIRECT("1:"&LEN(G10&"")))/(MID(G10&"",ROW(INDIRECT("1:"&LEN(G10&""))),1)<>"0"),1),999)), MID(G10&"",_xlfn.AGGREGATE(15,6,ROW(INDIRECT("1:"&LEN(G10&"")))/(MID(G10&"",ROW(INDIRECT("1:"&LEN(G10&""))),1)<>"0"),1),999) ), IFERROR(VALUE(G10),G10))} -> 7896261020382 | N10: =TEXT(relatorio[[#This Row],[Data Emissão]],"mmm") -> set | O10: =_xlfn.XLOOKUP(relatorio[[#This Row],[Número]],relatorio_Entrada_NF!A:A,relatorio_Entrada_NF!A:A,"Pendente") -> Pendente | P10: =_xlfn.XLOOKUP(relatorio[[#This Row],[Nome PJ Emitente]],Material!A:A,Material!B:B,"Medicamento") -> Medicamento | Q10: =IF(relatorio[[#This Row],[Natureza]]="Medicamento",_xlfn.XLOOKUP(relatorio[[#This Row],[EAN]],CadastroProd!U:U,CadastroProd!A:A," "),_xlfn.XLOOKUP(relatorio[[#This Row],['[Item'] Código]],CadastroProd!X:X,CadastroProd!A:A," ")) -> 2438 | R10: =IF(O10="Pendente",_xlfn.XLOOKUP(relatorio[[#This Row],[Número]],Relatório_CTE!A:A,Relatório_CTE!B:B,"Sem CTE")," ") -> 6778 | S10: =IF(relatorio[[#This Row],[NFs Entrada - Winthor]]="Pendente",_xlfn.XLOOKUP(relatorio[[#This Row],[Número]],Relatório_CTE!A:A,Relatório_CTE!H:H,"Sem CTE")," ") -> 45924 | T10: =(IF(relatorio[[#This Row],[NFs Entrada - Winthor]]="Pendente",IF(relatorio[[#This Row],[Dt. CTE]]="Sem CTE",relatorio[[#This Row],[Data Emissão]]+_xlfn.XLOOKUP(relatorio[[#This Row],[De_Para]],'Lead Time - Histórico (Fornec.)'!B:B,'Lead Time - Histórico (Fornec.)'!C:C),relatorio[[#This Row],[Dt. CTE]]+_xlfn.XLOOKUP(relatorio[[#This Row],[Cód. Winthor]],'Lead Time - Histórico (Produto)'!A:A,'Lead Time - Histórico (Produto)'!C:C))," ")) -> 45929 | U10: =IFERROR(IF(WEEKDAY(relatorio[[#This Row],[Previsão de entrega - Bruto]],2)=6,relatorio[[#This Row],[Previsão de entrega - Bruto]]+2,IF(WEEKDAY(relatorio[[#This Row],[Previsão de entrega - Bruto]],2)=7,relatorio[[#This Row],[Previsão de entrega - Bruto]]+1,relatorio[[#This Row],[Previsão de entrega - Bruto]]))," ") -> 45929
A11: PUBLICO | B11: CE | C11: Bayer S/A | D11: 288743 | E11: 45924 | F11: 70914.62 | G11: 7891106913881 | H11: 000000000086961458 | I11: NUBEQA 300MG TAFI BT 1X120 BR | J11: 46721 | K11: 6 | L11: =_xlfn.XLOOKUP(relatorio[[#This Row],[Nome PJ Emitente]],De_Para!A:A,De_Para!C:C) -> Bayer | M11: {=IF(LEFT(G11&"",1)="0", IFERROR( VALUE(MID(G11&"",_xlfn.AGGREGATE(15,6,ROW(INDIRECT("1:"&LEN(G11&"")))/(MID(G11&"",ROW(INDIRECT("1:"&LEN(G11&""))),1)<>"0"),1),999)), MID(G11&"",_xlfn.AGGREGATE(15,6,ROW(INDIRECT("1:"&LEN(G11&"")))/(MID(G11&"",ROW(INDIRECT("1:"&LEN(G11&""))),1)<>"0"),1),999) ), IFERROR(VALUE(G11),G11))} -> 7891106913881 | N11: =TEXT(relatorio[[#This Row],[Data Emissão]],"mmm") -> set | O11: =_xlfn.XLOOKUP(relatorio[[#This Row],[Número]],relatorio_Entrada_NF!A:A,relatorio_Entrada_NF!A:A,"Pendente") -> Pendente | P11: =_xlfn.XLOOKUP(relatorio[[#This Row],[Nome PJ Emitente]],Material!A:A,Material!B:B,"Medicamento") -> Medicamento | Q11: =IF(relatorio[[#This Row],[Natureza]]="Medicamento",_xlfn.XLOOKUP(relatorio[[#This Row],[EAN]],CadastroProd!U:U,CadastroProd!A:A," "),_xlfn.XLOOKUP(relatorio[[#This Row],['[Item'] Código]],CadastroProd!X:X,CadastroProd!A:A," ")) -> 2382 | R11: =IF(O11="Pendente",_xlfn.XLOOKUP(relatorio[[#This Row],[Número]],Relatório_CTE!A:A,Relatório_CTE!B:B,"Sem CTE")," ") -> Sem CTE | S11: =IF(relatorio[[#This Row],[NFs Entrada - Winthor]]="Pendente",_xlfn.XLOOKUP(relatorio[[#This Row],[Número]],Relatório_CTE!A:A,Relatório_CTE!H:H,"Sem CTE")," ") -> Sem CTE | T11: =(IF(relatorio[[#This Row],[NFs Entrada - Winthor]]="Pendente",IF(relatorio[[#This Row],[Dt. CTE]]="Sem CTE",relatorio[[#This Row],[Data Emissão]]+_xlfn.XLOOKUP(relatorio[[#This Row],[De_Para]],'Lead Time - Histórico (Fornec.)'!B:B,'Lead Time - Histórico (Fornec.)'!C:C),relatorio[[#This Row],[Dt. CTE]]+_xlfn.XLOOKUP(relatorio[[#This Row],[Cód. Winthor]],'Lead Time - Histórico (Produto)'!A:A,'Lead Time - Histórico (Produto)'!C:C))," ")) -> 45935 | U11: =IFERROR(IF(WEEKDAY(relatorio[[#This Row],[Previsão de entrega - Bruto]],2)=6,relatorio[[#This Row],[Previsão de entrega - Bruto]]+2,IF(WEEKDAY(relatorio[[#This Row],[Previsão de entrega - Bruto]],2)=7,relatorio[[#This Row],[Previsão de entrega - Bruto]]+1,relatorio[[#This Row],[Previsão de entrega - Bruto]]))," ") -> 45936
A12: PRIVADO | B12: CE | C12: Bayer S/A | D12: 288920 | E12: 45924 | F12: 176332.6 | G12: 7891106913881 | H12: 000000000086961458 | I12: NUBEQA 300MG TAFI BT 1X120 BR | J12: 46721 | K12: 15 | L12: =_xlfn.XLOOKUP(relatorio[[#This Row],[Nome PJ Emitente]],De_Para!A:A,De_Para!C:C) -> Bayer | M12: {=IF(LEFT(G12&"",1)="0", IFERROR( VALUE(MID(G12&"",_xlfn.AGGREGATE(15,6,ROW(INDIRECT("1:"&LEN(G12&"")))/(MID(G12&"",ROW(INDIRECT("1:"&LEN(G12&""))),1)<>"0"),1),999)), MID(G12&"",_xlfn.AGGREGATE(15,6,ROW(INDIRECT("1:"&LEN(G12&"")))/(MID(G12&"",ROW(INDIRECT("1:"&LEN(G12&""))),1)<>"0"),1),999) ), IFERROR(VALUE(G12),G12))} -> 7891106913881 | N12: =TEXT(relatorio[[#This Row],[Data Emissão]],"mmm") -> set | O12: =_xlfn.XLOOKUP(relatorio[[#This Row],[Número]],relatorio_Entrada_NF!A:A,relatorio_Entrada_NF!A:A,"Pendente") -> Pendente | P12: =_xlfn.XLOOKUP(relatorio[[#This Row],[Nome PJ Emitente]],Material!A:A,Material!B:B,"Medicamento") -> Medicamento | Q12: =IF(relatorio[[#This Row],[Natureza]]="Medicamento",_xlfn.XLOOKUP(relatorio[[#This Row],[EAN]],CadastroProd!U:U,CadastroProd!A:A," "),_xlfn.XLOOKUP(relatorio[[#This Row],['[Item'] Código]],CadastroProd!X:X,CadastroProd!A:A," ")) -> 2382 | R12: =IF(O12="Pendente",_xlfn.XLOOKUP(relatorio[[#This Row],[Número]],Relatório_CTE!A:A,Relatório_CTE!B:B,"Sem CTE")," ") -> Sem CTE | S12: =IF(relatorio[[#This Row],[NFs Entrada - Winthor]]="Pendente",_xlfn.XLOOKUP(relatorio[[#This Row],[Número]],Relatório_CTE!A:A,Relatório_CTE!H:H,"Sem CTE")," ") -> Sem CTE | T12: =(IF(relatorio[[#This Row],[NFs Entrada - Winthor]]="Pendente",IF(relatorio[[#This Row],[Dt. CTE]]="Sem CTE",relatorio[[#This Row],[Data Emissão]]+_xlfn.XLOOKUP(relatorio[[#This Row],[De_Para]],'Lead Time - Histórico (Fornec.)'!B:B,'Lead Time - Histórico (Fornec.)'!C:C),relatorio[[#This Row],[Dt. CTE]]+_xlfn.XLOOKUP(relatorio[[#This Row],[Cód. Winthor]],'Lead Time - Histórico (Produto)'!A:A,'Lead Time - Histórico (Produto)'!C:C))," ")) -> 45935 | U12: =IFERROR(IF(WEEKDAY(relatorio[[#This Row],[Previsão de entrega - Bruto]],2)=6,relatorio[[#This Row],[Previsão de entrega - Bruto]]+2,IF(WEEKDAY(relatorio[[#This Row],[Previsão de entrega - Bruto]],2)=7,relatorio[[#This Row],[Previsão de entrega - Bruto]]+1,relatorio[[#This Row],[Previsão de entrega - Bruto]]))," ") -> 45936
A13: PRIVADO | B13: CE | C13: LIBBS FARMACEUTICA Ltda | D13: 343366 | E13: 45924 | F13: 318.86 | G13: 7896094202818 | H13: 000000000000150926 | I13: ONTAX 300 MG OR | J13: 46568 | K13: 1 | L13: =_xlfn.XLOOKUP(relatorio[[#This Row],[Nome PJ Emitente]],De_Para!A:A,De_Para!C:C) -> Libbs | M13: {=IF(LEFT(G13&"",1)="0", IFERROR( VALUE(MID(G13&"",_xlfn.AGGREGATE(15,6,ROW(INDIRECT("1:"&LEN(G13&"")))/(MID(G13&"",ROW(INDIRECT("1:"&LEN(G13&""))),1)<>"0"),1),999)), MID(G13&"",_xlfn.AGGREGATE(15,6,ROW(INDIRECT("1:"&LEN(G13&"")))/(MID(G13&"",ROW(INDIRECT("1:"&LEN(G13&""))),1)<>"0"),1),999) ), IFERROR(VALUE(G13),G13))} -> 7896094202818 | N13: =TEXT(relatorio[[#This Row],[Data Emissão]],"mmm") -> set | O13: =_xlfn.XLOOKUP(relatorio[[#This Row],[Número]],relatorio_Entrada_NF!A:A,relatorio_Entrada_NF!A:A,"Pendente") -> Pendente | P13: =_xlfn.XLOOKUP(relatorio[[#This Row],[Nome PJ Emitente]],Material!A:A,Material!B:B,"Medicamento") -> Medicamento | Q13: =IF(relatorio[[#This Row],[Natureza]]="Medicamento",_xlfn.XLOOKUP(relatorio[[#This Row],[EAN]],CadastroProd!U:U,CadastroProd!A:A," "),_xlfn.XLOOKUP(relatorio[[#This Row],['[Item'] Código]],CadastroProd!X:X,CadastroProd!A:A," ")) -> 2575 | R13: =IF(O13="Pendente",_xlfn.XLOOKUP(relatorio[[#This Row],[Número]],Relatório_CTE!A:A,Relatório_CTE!B:B,"Sem CTE")," ") -> 914647 | S13: =IF(relatorio[[#This Row],[NFs Entrada - Winthor]]="Pendente",_xlfn.XLOOKUP(relatorio[[#This Row],[Número]],Relatório_CTE!A:A,Relatório_CTE!H:H,"Sem CTE")," ") -> 45925 | T13: =(IF(relatorio[[#This Row],[NFs Entrada - Winthor]]="Pendente",IF(relatorio[[#This Row],[Dt. CTE]]="Sem CTE",relatorio[[#This Row],[Data Emissão]]+_xlfn.XLOOKUP(relatorio[[#This Row],[De_Para]],'Lead Time - Histórico (Fornec.)'!B:B,'Lead Time - Histórico (Fornec.)'!C:C),relatorio[[#This Row],[Dt. CTE]]+_xlfn.XLOOKUP(relatorio[[#This Row],[Cód. Winthor]],'Lead Time - Histórico (Produto)'!A:A,'Lead Time - Histórico (Produto)'!C:C))," ")) -> 45931 | U13: =IFERROR(IF(WEEKDAY(relatorio[[#This Row],[Previsão de entrega - Bruto]],2)=6,relatorio[[#This Row],[Previsão de entrega - Bruto]]+2,IF(WEEKDAY(relatorio[[#This Row],[Previsão de entrega - Bruto]],2)=7,relatorio[[#This Row],[Previsão de entrega - Bruto]]+1,relatorio[[#This Row],[Previsão de entrega - Bruto]]))," ") -> 45931
... A83: PRIVADO | B83: PE | C83: CELLTRION HEALTHCARE DIST PROD FARMACEUTICOS DO BRASIL LTDA | D83: 8207 | E83: 45919 | F83: 66240 | G83: 7898576550035 | H83: M06fDP440IVX1 | I83: HERZUMA 440 MG/20ML LOTE 5A6C222 Fab.:5/7/2025 Val.:2/28/2031 | J83: 47907 | K83: 48 | L83: =_xlfn.XLOOKUP(relatorio[[#This Row],[Nome PJ Emitente]],De_Para!A:A,De_Para!C:C) -> Celltrion | M83: {=IF(LEFT(G83&"",1)="0", IFERROR( VALUE(MID(G83&"",_xlfn.AGGREGATE(15,6,ROW(INDIRECT("1:"&LEN(G83&"")))/(MID(G83&"",ROW(INDIRECT("1:"&LEN(G83&""))),1)<>"0"),1),999)), MID(G83&"",_xlfn.AGGREGATE(15,6,ROW(INDIRECT("1:"&LEN(G83&"")))/(MID(G83&"",ROW(INDIRECT("1:"&LEN(G83&""))),1)<>"0"),1),999) ), IFERROR(VALUE(G83),G83))} -> 7898576550035 | N83: =TEXT(relatorio[[#This Row],[Data Emissão]],"mmm") -> set | O83: =_xlfn.XLOOKUP(relatorio[[#This Row],[Número]],relatorio_Entrada_NF!A:A,relatorio_Entrada_NF!A:A,"Pendente") -> Pendente | P83: =_xlfn.XLOOKUP(relatorio[[#This Row],[Nome PJ Emitente]],Material!A:A,Material!B:B,"Medicamento") -> Medicamento | Q83: =IF(relatorio[[#This Row],[Natureza]]="Medicamento",_xlfn.XLOOKUP(relatorio[[#This Row],[EAN]],CadastroProd!U:U,CadastroProd!A:A," "),_xlfn.XLOOKUP(relatorio[[#This Row],['[Item'] Código]],CadastroProd!X:X,CadastroProd!A:A," ")) -> 2421 | R83: =IF(O83="Pendente",_xlfn.XLOOKUP(relatorio[[#This Row],[Número]],Relatório_CTE!A:A,Relatório_CTE!B:B,"Sem CTE")," ") -> 44718 | S83: =IF(relatorio[[#This Row],[NFs Entrada - Winthor]]="Pendente",_xlfn.XLOOKUP(relatorio[[#This Row],[Número]],Relatório_CTE!A:A,Relatório_CTE!H:H,"Sem CTE")," ") -> 45923 | T83: =(IF(relatorio[[#This Row],[NFs Entrada - Winthor]]="Pendente",IF(relatorio[[#This Row],[Dt. CTE]]="Sem CTE",relatorio[[#This Row],[Data Emissão]]+_xlfn.XLOOKUP(relatorio[[#This Row],[De_Para]],'Lead Time - Histórico (Fornec.)'!B:B,'Lead Time - Histórico (Fornec.)'!C:C),relatorio[[#This Row],[Dt. CTE]]+_xlfn.XLOOKUP(relatorio[[#This Row],[Cód. Winthor]],'Lead Time - Histórico (Produto)'!A:A,'Lead Time - Histórico (Produto)'!C:C))," ")) -> 45927 | U83: =IFERROR(IF(WEEKDAY(relatorio[[#This Row],[Previsão de entrega - Bruto]],2)=6,relatorio[[#This Row],[Previsão de entrega - Bruto]]+2,IF(WEEKDAY(relatorio[[#This Row],[Previsão de entrega - Bruto]],2)=7,relatorio[[#This Row],[Previsão de entrega - Bruto]]+1,relatorio[[#This Row],[Previsão de entrega - Bruto]]))," ") -> 45929
A84: PUBLICO | B84: PE | C84: GABISA MEDICAL INTERNATIONAL S.A. | D84: 36372 | E84: 45919 | F84: 4904.17 | G84: 7898943128010 | H84: 230-06 | I84: CANULA NASAL PARA OXIGENOTERAPIA GMI FR:06 - 2,10 M (NEONATAL) | K84: 300 | L84: =_xlfn.XLOOKUP(relatorio[[#This Row],[Nome PJ Emitente]],De_Para!A:A,De_Para!C:C) -> GMI | M84: {=IF(LEFT(G84&"",1)="0", IFERROR( VALUE(MID(G84&"",_xlfn.AGGREGATE(15,6,ROW(INDIRECT("1:"&LEN(G84&"")))/(MID(G84&"",ROW(INDIRECT("1:"&LEN(G84&""))),1)<>"0"),1),999)), MID(G84&"",_xlfn.AGGREGATE(15,6,ROW(INDIRECT("1:"&LEN(G84&"")))/(MID(G84&"",ROW(INDIRECT("1:"&LEN(G84&""))),1)<>"0"),1),999) ), IFERROR(VALUE(G84),G84))} -> 7898943128010 | N84: =TEXT(relatorio[[#This Row],[Data Emissão]],"mmm") -> set | O84: =_xlfn.XLOOKUP(relatorio[[#This Row],[Número]],relatorio_Entrada_NF!A:A,relatorio_Entrada_NF!A:A,"Pendente") -> Pendente | P84: =_xlfn.XLOOKUP(relatorio[[#This Row],[Nome PJ Emitente]],Material!A:A,Material!B:B,"Medicamento") -> Material | Q84: =IF(relatorio[[#This Row],[Natureza]]="Medicamento",_xlfn.XLOOKUP(relatorio[[#This Row],[EAN]],CadastroProd!U:U,CadastroProd!A:A," "),_xlfn.XLOOKUP(relatorio[[#This Row],['[Item'] Código]],CadastroProd!X:X,CadastroProd!A:A," ")) -> 3143 | R84: =IF(O84="Pendente",_xlfn.XLOOKUP(relatorio[[#This Row],[Número]],Relatório_CTE!A:A,Relatório_CTE!B:B,"Sem CTE")," ") -> 11121064 | S84: =IF(relatorio[[#This Row],[NFs Entrada - Winthor]]="Pendente",_xlfn.XLOOKUP(relatorio[[#This Row],[Número]],Relatório_CTE!A:A,Relatório_CTE!H:H,"Sem CTE")," ") -> 45925 | T84: =(IF(relatorio[[#This Row],[NFs Entrada - Winthor]]="Pendente",IF(relatorio[[#This Row],[Dt. CTE]]="Sem CTE",relatorio[[#This Row],[Data Emissão]]+_xlfn.XLOOKUP(relatorio[[#This Row],[De_Para]],'Lead Time - Histórico (Fornec.)'!B:B,'Lead Time - Histórico (Fornec.)'!C:C),relatorio[[#This Row],[Dt. CTE]]+_xlfn.XLOOKUP(relatorio[[#This Row],[Cód. Winthor]],'Lead Time - Histórico (Produto)'!A:A,'Lead Time - Histórico (Produto)'!C:C))," ")) -> 45942 | U84: =IFERROR(IF(WEEKDAY(relatorio[[#This Row],[Previsão de entrega - Bruto]],2)=6,relatorio[[#This Row],[Previsão de entrega - Bruto]]+2,IF(WEEKDAY(relatorio[[#This Row],[Previsão de entrega - Bruto]],2)=7,relatorio[[#This Row],[Previsão de entrega - Bruto]]+1,relatorio[[#This Row],[Previsão de entrega - Bruto]]))," ") -> 45943
A85: PUBLICO | B85: PE | C85: 3M DO BRASIL LTDA | D85: 511798 | E85: 45919 | F85: 50686.4 | G85: 50707387802252 | H85: HB004800296 | I85: 1657R TEGADERM CHG CX C/25 3M TEGADERM CHG | J85: 46471 | K85: 40 | L85: =_xlfn.XLOOKUP(relatorio[[#This Row],[Nome PJ Emitente]],De_Para!A:A,De_Para!C:C) -> 3M | M85: {=IF(LEFT(G85&"",1)="0", IFERROR( VALUE(MID(G85&"",_xlfn.AGGREGATE(15,6,ROW(INDIRECT("1:"&LEN(G85&"")))/(MID(G85&"",ROW(INDIRECT("1:"&LEN(G85&""))),1)<>"0"),1),999)), MID(G85&"",_xlfn.AGGREGATE(15,6,ROW(INDIRECT("1:"&LEN(G85&"")))/(MID(G85&"",ROW(INDIRECT("1:"&LEN(G85&""))),1)<>"0"),1),999) ), IFERROR(VALUE(G85),G85))} -> 50707387802252 | N85: =TEXT(relatorio[[#This Row],[Data Emissão]],"mmm") -> set | O85: =_xlfn.XLOOKUP(relatorio[[#This Row],[Número]],relatorio_Entrada_NF!A:A,relatorio_Entrada_NF!A:A,"Pendente") -> Pendente | P85: =_xlfn.XLOOKUP(relatorio[[#This Row],[Nome PJ Emitente]],Material!A:A,Material!B:B,"Medicamento") -> Material | Q85: =IF(relatorio[[#This Row],[Natureza]]="Medicamento",_xlfn.XLOOKUP(relatorio[[#This Row],[EAN]],CadastroProd!U:U,CadastroProd!A:A," "),_xlfn.XLOOKUP(relatorio[[#This Row],['[Item'] Código]],CadastroProd!X:X,CadastroProd!A:A," ")) -> 3329 | R85: =IF(O85="Pendente",_xlfn.XLOOKUP(relatorio[[#This Row],[Número]],Relatório_CTE!A:A,Relatório_CTE!B:B,"Sem CTE")," ") -> 2314657 | S85: =IF(relatorio[[#This Row],[NFs Entrada - Winthor]]="Pendente",_xlfn.XLOOKUP(relatorio[[#This Row],[Número]],Relatório_CTE!A:A,Relatório_CTE!H:H,"Sem CTE")," ") -> 45919 | T85: =(IF(relatorio[[#This Row],[NFs Entrada - Winthor]]="Pendente",IF(relatorio[[#This Row],[Dt. CTE]]="Sem CTE",relatorio[[#This Row],[Data Emissão]]+_xlfn.XLOOKUP(relatorio[[#This Row],[De_Para]],'Lead Time - Histórico (Fornec.)'!B:B,'Lead Time - Histórico (Fornec.)'!C:C),relatorio[[#This Row],[Dt. CTE]]+_xlfn.XLOOKUP(relatorio[[#This Row],[Cód. Winthor]],'Lead Time - Histórico (Produto)'!A:A,'Lead Time - Histórico (Produto)'!C:C))," ")) -> 45933 | U85: =IFERROR(IF(WEEKDAY(relatorio[[#This Row],[Previsão de entrega - Bruto]],2)=6,relatorio[[#This Row],[Previsão de entrega - Bruto]]+2,IF(WEEKDAY(relatorio[[#This Row],[Previsão de entrega - Bruto]],2)=7,relatorio[[#This Row],[Previsão de entrega - Bruto]]+1,relatorio[[#This Row],[Previsão de entrega - Bruto]]))," ") -> 45933
A86: PRIVADO | B86: PE | C86: NOVARTIS BIOCIENCIAS SA | D86: 501817 | E86: 45919 | F86: 20125.53 | G86: 7896261020689 | H86: 751315 | I86: REVOLADE 50MG 14 CE | J86: 46446 | K86: 5 | L86: =_xlfn.XLOOKUP(relatorio[[#This Row],[Nome PJ Emitente]],De_Para!A:A,De_Para!C:C) -> Novartis | M86: {=IF(LEFT(G86&"",1)="0", IFERROR( VALUE(MID(G86&"",_xlfn.AGGREGATE(15,6,ROW(INDIRECT("1:"&LEN(G86&"")))/(MID(G86&"",ROW(INDIRECT("1:"&LEN(G86&""))),1)<>"0"),1),999)), MID(G86&"",_xlfn.AGGREGATE(15,6,ROW(INDIRECT("1:"&LEN(G86&"")))/(MID(G86&"",ROW(INDIRECT("1:"&LEN(G86&""))),1)<>"0"),1),999) ), IFERROR(VALUE(G86),G86))} -> 7896261020689 | N86: =TEXT(relatorio[[#This Row],[Data Emissão]],"mmm") -> set | O86: =_xlfn.XLOOKUP(relatorio[[#This Row],[Número]],relatorio_Entrada_NF!A:A,relatorio_Entrada_NF!A:A,"Pendente") -> Pendente | P86: =_xlfn.XLOOKUP(relatorio[[#This Row],[Nome PJ Emitente]],Material!A:A,Material!B:B,"Medicamento") -> Medicamento | Q86: =IF(relatorio[[#This Row],[Natureza]]="Medicamento",_xlfn.XLOOKUP(relatorio[[#This Row],[EAN]],CadastroProd!U:U,CadastroProd!A:A," "),_xlfn.XLOOKUP(relatorio[[#This Row],['[Item'] Código]],CadastroProd!X:X,CadastroProd!A:A," ")) -> 1344 | R86: =IF(O86="Pendente",_xlfn.XLOOKUP(relatorio[[#This Row],[Número]],Relatório_CTE!A:A,Relatório_CTE!B:B,"Sem CTE")," ") -> 382539 | S86: =IF(relatorio[[#This Row],[NFs Entrada - Winthor]]="Pendente",_xlfn.XLOOKUP(relatorio[[#This Row],[Número]],Relatório_CTE!A:A,Relatório_CTE!H:H,"Sem CTE")," ") -> 45923 | T86: =(IF(relatorio[[#This Row],[NFs Entrada - Winthor]]="Pendente",IF(relatorio[[#This Row],[Dt. CTE]]="Sem CTE",relatorio[[#This Row],[Data Emissão]]+_xlfn.XLOOKUP(relatorio[[#This Row],[De_Para]],'Lead Time - Histórico (Fornec.)'!B:B,'Lead Time - Histórico (Fornec.)'!C:C),relatorio[[#This Row],[Dt. CTE]]+_xlfn.XLOOKUP(relatorio[[#This Row],[Cód. Winthor]],'Lead Time - Histórico (Produto)'!A:A,'Lead Time - Histórico (Produto)'!C:C))," ")) -> 45928 | U86: =IFERROR(IF(WEEKDAY(relatorio[[#This Row],[Previsão de entrega - Bruto]],2)=6,relatorio[[#This Row],[Previsão de entrega - Bruto]]+2,IF(WEEKDAY(relatorio[[#This Row],[Previsão de entrega - Bruto]],2)=7,relatorio[[#This Row],[Previsão de entrega - Bruto]]+1,relatorio[[#This Row],[Previsão de entrega - Bruto]]))," ") -> 45929
A87: PRIVADO | B87: PB | C87: ABBVIE FARMACEUTICA LTDA | D87: 152020 | E87: 45919 | F87: 292555.35 | G87: 07897316802939 | H87: 91223BR | I87: BOTOX 100 Units/Vial | J87: 46507 | K87: 74 | L87: =_xlfn.XLOOKUP(relatorio[[#This Row],[Nome PJ Emitente]],De_Para!A:A,De_Para!C:C) -> Abbvie | M87: {=IF(LEFT(G87&"",1)="0", IFERROR( VALUE(MID(G87&"",_xlfn.AGGREGATE(15,6,ROW(INDIRECT("1:"&LEN(G87&"")))/(MID(G87&"",ROW(INDIRECT("1:"&LEN(G87&""))),1)<>"0"),1),999)), MID(G87&"",_xlfn.AGGREGATE(15,6,ROW(INDIRECT("1:"&LEN(G87&"")))/(MID(G87&"",ROW(INDIRECT("1:"&LEN(G87&""))),1)<>"0"),1),999) ), IFERROR(VALUE(G87),G87))} -> 7897316802939 | N87: =TEXT(relatorio[[#This Row],[Data Emissão]],"mmm") -> set | O87: =_xlfn.XLOOKUP(relatorio[[#This Row],[Número]],relatorio_Entrada_NF!A:A,relatorio_Entrada_NF!A:A,"Pendente") -> 152020 | P87: =_xlfn.XLOOKUP(relatorio[[#This Row],[Nome PJ Emitente]],Material!A:A,Material!B:B,"Medicamento") -> Medicamento | Q87: =IF(relatorio[[#This Row],[Natureza]]="Medicamento",_xlfn.XLOOKUP(relatorio[[#This Row],[EAN]],CadastroProd!U:U,CadastroProd!A:A," "),_xlfn.XLOOKUP(relatorio[[#This Row],['[Item'] Código]],CadastroProd!X:X,CadastroProd!A:A," ")) -> 2938 | R87: =IF(O87="Pendente",_xlfn.XLOOKUP(relatorio[[#This Row],[Número]],Relatório_CTE!A:A,Relatório_CTE!B:B,"Sem CTE")," ") | S87: =IF(relatorio[[#This Row],[NFs Entrada - Winthor]]="Pendente",_xlfn.XLOOKUP(relatorio[[#This Row],[Número]],Relatório_CTE!A:A,Relatório_CTE!H:H,"Sem CTE")," ") | T87: =(IF(relatorio[[#This Row],[NFs Entrada - Winthor]]="Pendente",IF(relatorio[[#This Row],[Dt. CTE]]="Sem CTE",relatorio[[#This Row],[Data Emissão]]+_xlfn.XLOOKUP(relatorio[[#This Row],[De_Para]],'Lead Time - Histórico (Fornec.)'!B:B,'Lead Time - Histórico (Fornec.)'!C:C),relatorio[[#This Row],[Dt. CTE]]+_xlfn.XLOOKUP(relatorio[[#This Row],[Cód. Winthor]],'Lead Time - Histórico (Produto)'!A:A,'Lead Time - Histórico (Produto)'!C:C))," ")) | U87: =IFERROR(IF(WEEKDAY(relatorio[[#This Row],[Previsão de entrega - Bruto]],2)=6,relatorio[[#This Row],[Previsão de entrega - Bruto]]+2,IF(WEEKDAY(relatorio[[#This Row],[Previsão de entrega - Bruto]],2)=7,relatorio[[#This Row],[Previsão de entrega - Bruto]]+1,relatorio[[#This Row],[Previsão de entrega - Bruto]]))," ")
A88: PRIVADO | B88: PB | C88: ABBVIE FARMACEUTICA LTDA | D88: 152020 | E88: 45919 | F88: 292555.35 | G88: 07897316805015 | H88: 93251BR | I88: BOTOX 200 Units/Vial | J88: 46538 | K88: 163 | L88: =_xlfn.XLOOKUP(relatorio[[#This Row],[Nome PJ Emitente]],De_Para!A:A,De_Para!C:C) -> Abbvie | M88: {=IF(LEFT(G88&"",1)="0", IFERROR( VALUE(MID(G88&"",_xlfn.AGGREGATE(15,6,ROW(INDIRECT("1:"&LEN(G88&"")))/(MID(G88&"",ROW(INDIRECT("1:"&LEN(G88&""))),1)<>"0"),1),999)), MID(G88&"",_xlfn.AGGREGATE(15,6,ROW(INDIRECT("1:"&LEN(G88&"")))/(MID(G88&"",ROW(INDIRECT("1:"&LEN(G88&""))),1)<>"0"),1),999) ), IFERROR(VALUE(G88),G88))} -> 7897316805015 | N88: =TEXT(relatorio[[#This Row],[Data Emissão]],"mmm") -> set | O88: =_xlfn.XLOOKUP(relatorio[[#This Row],[Número]],relatorio_Entrada_NF!A:A,relatorio_Entrada_NF!A:A,"Pendente") -> 152020 | P88: =_xlfn.XLOOKUP(relatorio[[#This Row],[Nome PJ Emitente]],Material!A:A,Material!B:B,"Medicamento") -> Medicamento | Q88: =IF(relatorio[[#This Row],[Natureza]]="Medicamento",_xlfn.XLOOKUP(relatorio[[#This Row],[EAN]],CadastroProd!U:U,CadastroProd!A:A," "),_xlfn.XLOOKUP(relatorio[[#This Row],['[Item'] Código]],CadastroProd!X:X,CadastroProd!A:A," ")) -> 2940 | R88: =IF(O88="Pendente",_xlfn.XLOOKUP(relatorio[[#This Row],[Número]],Relatório_CTE!A:A,Relatório_CTE!B:B,"Sem CTE")," ") | S88: =IF(relatorio[[#This Row],[NFs Entrada - Winthor]]="Pendente",_xlfn.XLOOKUP(relatorio[[#This Row],[Número]],Relatório_CTE!A:A,Relatório_CTE!H:H,"Sem CTE")," ") | T88: =(IF(relatorio[[#This Row],[NFs Entrada - Winthor]]="Pendente",IF(relatorio[[#This Row],[Dt. CTE]]="Sem CTE",relatorio[[#This Row],[Data Emissão]]+_xlfn.XLOOKUP(relatorio[[#This Row],[De_Para]],'Lead Time - Histórico (Fornec.)'!B:B,'Lead Time - Histórico (Fornec.)'!C:C),relatorio[[#This Row],[Dt. CTE]]+_xlfn.XLOOKUP(relatorio[[#This Row],[Cód. Winthor]],'Lead Time - Histórico (Produto)'!A:A,'Lead Time - Histórico (Produto)'!C:C))," ")) | U88: =IFERROR(IF(WEEKDAY(relatorio[[#This Row],[Previsão de entrega - Bruto]],2)=6,relatorio[[#This Row],[Previsão de entrega - Bruto]]+2,IF(WEEKDAY(relatorio[[#This Row],[Previsão de entrega - Bruto]],2)=7,relatorio[[#This Row],[Previsão de entrega - Bruto]]+1,relatorio[[#This Row],[Previsão de entrega - Bruto]]))," ")
A89: PRIVADO | B89: PB | C89: CELLTRION HEALTHCARE DIST PROD FARMACEUTICOS DO BRASIL LTDA | D89: 8204 | E89: 45919 | F89: 52231.2 | G89: 7898576550332 | H89: M17fDP040AIX1 | I89: YUFLYMA SC 40MG/0,4ML LOTE 3LAT06T1D Fab.:9/19/2023 Val.:8/31/2026 | J89: 46265 | K89: 60 | L89: =_xlfn.XLOOKUP(relatorio[[#This Row],[Nome PJ Emitente]],De_Para!A:A,De_Para!C:C) -> Celltrion | M89: {=IF(LEFT(G89&"",1)="0", IFERROR( VALUE(MID(G89&"",_xlfn.AGGREGATE(15,6,ROW(INDIRECT("1:"&LEN(G89&"")))/(MID(G89&"",ROW(INDIRECT("1:"&LEN(G89&""))),1)<>"0"),1),999)), MID(G89&"",_xlfn.AGGREGATE(15,6,ROW(INDIRECT("1:"&LEN(G89&"")))/(MID(G89&"",ROW(INDIRECT("1:"&LEN(G89&""))),1)<>"0"),1),999) ), IFERROR(VALUE(G89),G89))} -> 7898576550332 | N89: =TEXT(relatorio[[#This Row],[Data Emissão]],"mmm") -> set | O89: =_xlfn.XLOOKUP(relatorio[[#This Row],[Número]],relatorio_Entrada_NF!A:A,relatorio_Entrada_NF!A:A,"Pendente") -> Pendente | P89: =_xlfn.XLOOKUP(relatorio[[#This Row],[Nome PJ Emitente]],Material!A:A,Material!B:B,"Medicamento") -> Medicamento | Q89: =IF(relatorio[[#This Row],[Natureza]]="Medicamento",_xlfn.XLOOKUP(relatorio[[#This Row],[EAN]],CadastroProd!U:U,CadastroProd!A:A," "),_xlfn.XLOOKUP(relatorio[[#This Row],['[Item'] Código]],CadastroProd!X:X,CadastroProd!A:A," ")) -> 3280 | R89: =IF(O89="Pendente",_xlfn.XLOOKUP(relatorio[[#This Row],[Número]],Relatório_CTE!A:A,Relatório_CTE!B:B,"Sem CTE")," ") -> 44711 | S89: =IF(relatorio[[#This Row],[NFs Entrada - Winthor]]="Pendente",_xlfn.XLOOKUP(relatorio[[#This Row],[Número]],Relatório_CTE!A:A,Relatório_CTE!H:H,"Sem CTE")," ") -> 45923 | T89: =(IF(relatorio[[#This Row],[NFs Entrada - Winthor]]="Pendente",IF(relatorio[[#This Row],[Dt. CTE]]="Sem CTE",relatorio[[#This Row],[Data Emissão]]+_xlfn.XLOOKUP(relatorio[[#This Row],[De_Para]],'Lead Time - Histórico (Fornec.)'!B:B,'Lead Time - Histórico (Fornec.)'!C:C),relatorio[[#This Row],[Dt. CTE]]+_xlfn.XLOOKUP(relatorio[[#This Row],[Cód. Winthor]],'Lead Time - Histórico (Produto)'!A:A,'Lead Time - Histórico (Produto)'!C:C))," ")) -> 45926 | U89: =IFERROR(IF(WEEKDAY(relatorio[[#This Row],[Previsão de entrega - Bruto]],2)=6,relatorio[[#This Row],[Previsão de entrega - Bruto]]+2,IF(WEEKDAY(relatorio[[#This Row],[Previsão de entrega - Bruto]],2)=7,relatorio[[#This Row],[Previsão de entrega - Bruto]]+1,relatorio[[#This Row],[Previsão de entrega - Bruto]]))," ") -> 45926
A90: PRIVADO | B90: PB | C90: GABISA MEDICAL INTERNATIONAL S.A. | D90: 36370 | E90: 45919 | F90: 2827.7 | G90: 7898943128010 | H90: 230-06 | I90: CANULA NASAL PARA OXIGENOTERAPIA GMI FR:06 - 2,10 M (NEONATAL) | K90: 144 | L90: =_xlfn.XLOOKUP(relatorio[[#This Row],[Nome PJ Emitente]],De_Para!A:A,De_Para!C:C) -> GMI | M90: {=IF(LEFT(G90&"",1)="0", IFERROR( VALUE(MID(G90&"",_xlfn.AGGREGATE(15,6,ROW(INDIRECT("1:"&LEN(G90&"")))/(MID(G90&"",ROW(INDIRECT("1:"&LEN(G90&""))),1)<>"0"),1),999)), MID(G90&"",_xlfn.AGGREGATE(15,6,ROW(INDIRECT("1:"&LEN(G90&"")))/(MID(G90&"",ROW(INDIRECT("1:"&LEN(G90&""))),1)<>"0"),1),999) ), IFERROR(VALUE(G90),G90))} -> 7898943128010 | N90: =TEXT(relatorio[[#This Row],[Data Emissão]],"mmm") -> set | O90: =_xlfn.XLOOKUP(relatorio[[#This Row],[Número]],relatorio_Entrada_NF!A:A,relatorio_Entrada_NF!A:A,"Pendente") -> Pendente | P90: =_xlfn.XLOOKUP(relatorio[[#This Row],[Nome PJ Emitente]],Material!A:A,Material!B:B,"Medicamento") -> Material | Q90: =IF(relatorio[[#This Row],[Natureza]]="Medicamento",_xlfn.XLOOKUP(relatorio[[#This Row],[EAN]],CadastroProd!U:U,CadastroProd!A:A," "),_xlfn.XLOOKUP(relatorio[[#This Row],['[Item'] Código]],CadastroProd!X:X,CadastroProd!A:A," ")) -> 3143 | R90: =IF(O90="Pendente",_xlfn.XLOOKUP(relatorio[[#This Row],[Número]],Relatório_CTE!A:A,Relatório_CTE!B:B,"Sem CTE")," ") -> 11121010 | S90: =IF(relatorio[[#This Row],[NFs Entrada - Winthor]]="Pendente",_xlfn.XLOOKUP(relatorio[[#This Row],[Número]],Relatório_CTE!A:A,Relatório_CTE!H:H,"Sem CTE")," ") -> 45925 | T90: =(IF(relatorio[[#This Row],[NFs Entrada - Winthor]]="Pendente",IF(relatorio[[#This Row],[Dt. CTE]]="Sem CTE",relatorio[[#This Row],[Data Emissão]]+_xlfn.XLOOKUP(relatorio[[#This Row],[De_Para]],'Lead Time - Histórico (Fornec.)'!B:B,'Lead Time - Histórico (Fornec.)'!C:C),relatorio[[#This Row],[Dt. CTE]]+_xlfn.XLOOKUP(relatorio[[#This Row],[Cód. Winthor]],'Lead Time - Histórico (Produto)'!A:A,'Lead Time - Histórico (Produto)'!C:C))," ")) -> 45942 | U90: =IFERROR(IF(WEEKDAY(relatorio[[#This Row],[Previsão de entrega - Bruto]],2)=6,relatorio[[#This Row],[Previsão de entrega - Bruto]]+2,IF(WEEKDAY(relatorio[[#This Row],[Previsão de entrega - Bruto]],2)=7,relatorio[[#This Row],[Previsão de entrega - Bruto]]+1,relatorio[[#This Row],[Previsão de entrega - Bruto]]))," ") -> 45943
